<?xml version="1.0" encoding="utf-8"?>
<assemblies>
  <assembly name="WebApplicationBasicTesting.dll" environment="64-bit .NET (unknown version) [collection-per-class, parallel (8 threads)]" test-framework="xUnit.net 2.2.0.3300" run-date="2017-01-11" run-time="16:23:04" total="2" passed="1" failed="1" skipped="0" time="0.737" errors="0">
    <errors />
    <collection total="2" passed="1" failed="1" skipped="0" name="Test collection for Tests.Tests" time="0.588">
      <test name="Tests.Tests.IndexShouldIncludeStudentsData" type="Tests.Tests" method="IndexShouldIncludeStudentsData" time="0.566896" result="Fail">
        <failure exception-type="Xunit.Sdk.EqualException">
          <message><![CDATA[Assert.Equal() Failure\nExpected: 9\nActual:   8]]></message>
          <stack-trace><![CDATA[   at Tests.Tests.<IndexShouldIncludeStudentsData>d__4.MoveNext() in /home/nishant/workspace/dot_net_playground/asp_mvc/WebApplicationBasicWithUnitTesting/WebApplicationBasicTesting/Tests.cs:line 47
--- End of stack trace from previous location where exception was thrown ---
   at System.Runtime.ExceptionServices.ExceptionDispatchInfo.Throw()
   at System.Runtime.CompilerServices.TaskAwaiter.HandleNonSuccessAndDebuggerNotification(Task task)
--- End of stack trace from previous location where exception was thrown ---
   at System.Runtime.ExceptionServices.ExceptionDispatchInfo.Throw()
   at System.Runtime.CompilerServices.TaskAwaiter.HandleNonSuccessAndDebuggerNotification(Task task)
--- End of stack trace from previous location where exception was thrown ---
   at System.Runtime.ExceptionServices.ExceptionDispatchInfo.Throw()
   at System.Runtime.CompilerServices.TaskAwaiter.HandleNonSuccessAndDebuggerNotification(Task task)]]></stack-trace>
        </failure>
      </test>
      <test name="Tests.Tests.IndexShouldIncludeStudentsDataWithExactCount" type="Tests.Tests" method="IndexShouldIncludeStudentsDataWithExactCount" time="0.0215454" result="Pass" />
    </collection>
  </assembly>
</assemblies>